{
 "cells": [
  {
   "cell_type": "code",
   "execution_count": 4,
   "id": "799a3421-e0fe-4a8b-a16a-885b941e869f",
   "metadata": {},
   "outputs": [
    {
     "name": "stdout",
     "output_type": "stream",
     "text": [
      "Requirement already satisfied: pytao in /usr/local/Cellar/jupyterlab/3.4.7/libexec/lib/python3.10/site-packages (0.3)\n",
      "Note: you may need to restart the kernel to use updated packages.\n"
     ]
    }
   ],
   "source": [
    "pip install pytao"
   ]
  },
  {
   "cell_type": "code",
   "execution_count": 9,
   "id": "ae678602-9178-4135-a088-30fadc73bdf1",
   "metadata": {},
   "outputs": [
    {
     "ename": "NameError",
     "evalue": "name 'accinfo' is not defined",
     "output_type": "error",
     "traceback": [
      "\u001b[0;31m---------------------------------------------------------------------------\u001b[0m",
      "\u001b[0;31mNameError\u001b[0m                                 Traceback (most recent call last)",
      "Cell \u001b[0;32mIn [9], line 1\u001b[0m\n\u001b[0;32m----> 1\u001b[0m \u001b[43maccinfo\u001b[49m\n",
      "\u001b[0;31mNameError\u001b[0m: name 'accinfo' is not defined"
     ]
    }
   ],
   "source": [
    "accinfo"
   ]
  },
  {
   "cell_type": "code",
   "execution_count": 2,
   "id": "f714074b-61a1-4555-9b2a-41938c0265f4",
   "metadata": {},
   "outputs": [
    {
     "ename": "ValueError",
     "evalue": "The python kernel does not appear to be a conda environment.  Please use ``%pip install`` instead.",
     "output_type": "error",
     "traceback": [
      "\u001b[0;31m---------------------------------------------------------------------------\u001b[0m",
      "\u001b[0;31mValueError\u001b[0m                                Traceback (most recent call last)",
      "Cell \u001b[0;32mIn [2], line 1\u001b[0m\n\u001b[0;32m----> 1\u001b[0m \u001b[43mget_ipython\u001b[49m\u001b[43m(\u001b[49m\u001b[43m)\u001b[49m\u001b[38;5;241;43m.\u001b[39;49m\u001b[43mrun_line_magic\u001b[49m\u001b[43m(\u001b[49m\u001b[38;5;124;43m'\u001b[39;49m\u001b[38;5;124;43mconda\u001b[39;49m\u001b[38;5;124;43m'\u001b[39;49m\u001b[43m,\u001b[49m\u001b[43m \u001b[49m\u001b[38;5;124;43m'\u001b[39;49m\u001b[38;5;124;43minstall -c conda-forge bmad\u001b[39;49m\u001b[38;5;124;43m'\u001b[39;49m\u001b[43m)\u001b[49m\n",
      "File \u001b[0;32m/usr/local/Cellar/jupyterlab/3.4.7/libexec/lib/python3.10/site-packages/IPython/core/interactiveshell.py:2309\u001b[0m, in \u001b[0;36mInteractiveShell.run_line_magic\u001b[0;34m(self, magic_name, line, _stack_depth)\u001b[0m\n\u001b[1;32m   2307\u001b[0m     kwargs[\u001b[38;5;124m'\u001b[39m\u001b[38;5;124mlocal_ns\u001b[39m\u001b[38;5;124m'\u001b[39m] \u001b[38;5;241m=\u001b[39m \u001b[38;5;28mself\u001b[39m\u001b[38;5;241m.\u001b[39mget_local_scope(stack_depth)\n\u001b[1;32m   2308\u001b[0m \u001b[38;5;28;01mwith\u001b[39;00m \u001b[38;5;28mself\u001b[39m\u001b[38;5;241m.\u001b[39mbuiltin_trap:\n\u001b[0;32m-> 2309\u001b[0m     result \u001b[38;5;241m=\u001b[39m \u001b[43mfn\u001b[49m\u001b[43m(\u001b[49m\u001b[38;5;241;43m*\u001b[39;49m\u001b[43margs\u001b[49m\u001b[43m,\u001b[49m\u001b[43m \u001b[49m\u001b[38;5;241;43m*\u001b[39;49m\u001b[38;5;241;43m*\u001b[39;49m\u001b[43mkwargs\u001b[49m\u001b[43m)\u001b[49m\n\u001b[1;32m   2310\u001b[0m \u001b[38;5;28;01mreturn\u001b[39;00m result\n",
      "File \u001b[0;32m/usr/local/Cellar/jupyterlab/3.4.7/libexec/lib/python3.10/site-packages/IPython/core/magics/packaging.py:87\u001b[0m, in \u001b[0;36mPackagingMagics.conda\u001b[0;34m(self, line)\u001b[0m\n\u001b[1;32m     81\u001b[0m \u001b[38;5;124;03m\"\"\"Run the conda package manager within the current kernel.\u001b[39;00m\n\u001b[1;32m     82\u001b[0m \n\u001b[1;32m     83\u001b[0m \u001b[38;5;124;03mUsage:\u001b[39;00m\n\u001b[1;32m     84\u001b[0m \u001b[38;5;124;03m  %conda install [pkgs]\u001b[39;00m\n\u001b[1;32m     85\u001b[0m \u001b[38;5;124;03m\"\"\"\u001b[39;00m\n\u001b[1;32m     86\u001b[0m \u001b[38;5;28;01mif\u001b[39;00m \u001b[38;5;129;01mnot\u001b[39;00m _is_conda_environment():\n\u001b[0;32m---> 87\u001b[0m     \u001b[38;5;28;01mraise\u001b[39;00m \u001b[38;5;167;01mValueError\u001b[39;00m(\u001b[38;5;124m\"\u001b[39m\u001b[38;5;124mThe python kernel does not appear to be a conda environment.  \u001b[39m\u001b[38;5;124m\"\u001b[39m\n\u001b[1;32m     88\u001b[0m                      \u001b[38;5;124m\"\u001b[39m\u001b[38;5;124mPlease use ``\u001b[39m\u001b[38;5;124m%\u001b[39m\u001b[38;5;124mpip install`` instead.\u001b[39m\u001b[38;5;124m\"\u001b[39m)\n\u001b[1;32m     90\u001b[0m conda \u001b[38;5;241m=\u001b[39m _get_conda_executable()\n\u001b[1;32m     91\u001b[0m args \u001b[38;5;241m=\u001b[39m shlex\u001b[38;5;241m.\u001b[39msplit(line)\n",
      "\u001b[0;31mValueError\u001b[0m: The python kernel does not appear to be a conda environment.  Please use ``%pip install`` instead."
     ]
    }
   ],
   "source": [
    "conda install -c conda-forge bmad"
   ]
  },
  {
   "cell_type": "code",
   "execution_count": 3,
   "id": "34c4a33c-7dc9-4307-8e4d-5d048479a85a",
   "metadata": {},
   "outputs": [
    {
     "ename": "SyntaxError",
     "evalue": "invalid syntax (3414804088.py, line 1)",
     "output_type": "error",
     "traceback": [
      "\u001b[0;36m  Cell \u001b[0;32mIn [3], line 1\u001b[0;36m\u001b[0m\n\u001b[0;31m    install -c conda-forge bmad\u001b[0m\n\u001b[0m               ^\u001b[0m\n\u001b[0;31mSyntaxError\u001b[0m\u001b[0;31m:\u001b[0m invalid syntax\n"
     ]
    }
   ],
   "source": [
    "install -c conda-forge bmad"
   ]
  },
  {
   "cell_type": "code",
   "execution_count": 4,
   "id": "4eb164fc-a037-4103-9e98-d0f62d9e6fff",
   "metadata": {},
   "outputs": [
    {
     "ename": "SyntaxError",
     "evalue": "invalid syntax (258000529.py, line 1)",
     "output_type": "error",
     "traceback": [
      "\u001b[0;36m  Cell \u001b[0;32mIn [4], line 1\u001b[0;36m\u001b[0m\n\u001b[0;31m    pytao -init tao.init\u001b[0m\n\u001b[0m                ^\u001b[0m\n\u001b[0;31mSyntaxError\u001b[0m\u001b[0;31m:\u001b[0m invalid syntax\n"
     ]
    }
   ],
   "source": [
    "pytao -init tao.init"
   ]
  },
  {
   "cell_type": "code",
   "execution_count": 5,
   "id": "1ac4f20e-706e-40d2-8cba-71c4d3fa36c5",
   "metadata": {},
   "outputs": [
    {
     "ename": "SyntaxError",
     "evalue": "invalid syntax (258000529.py, line 1)",
     "output_type": "error",
     "traceback": [
      "\u001b[0;36m  Cell \u001b[0;32mIn [5], line 1\u001b[0;36m\u001b[0m\n\u001b[0;31m    pytao -init tao.init\u001b[0m\n\u001b[0m                ^\u001b[0m\n\u001b[0;31mSyntaxError\u001b[0m\u001b[0;31m:\u001b[0m invalid syntax\n"
     ]
    }
   ],
   "source": [
    "pytao -init tao.init"
   ]
  },
  {
   "cell_type": "code",
   "execution_count": 12,
   "id": "4cd48d38-fd3f-424b-a582-d82c3101612e",
   "metadata": {},
   "outputs": [
    {
     "ename": "NameError",
     "evalue": "name 'tao' is not defined",
     "output_type": "error",
     "traceback": [
      "\u001b[0;31m---------------------------------------------------------------------------\u001b[0m",
      "\u001b[0;31mNameError\u001b[0m                                 Traceback (most recent call last)",
      "Cell \u001b[0;32mIn [12], line 1\u001b[0m\n\u001b[0;32m----> 1\u001b[0m \u001b[43mtao\u001b[49m\n",
      "\u001b[0;31mNameError\u001b[0m: name 'tao' is not defined"
     ]
    }
   ],
   "source": [
    "tao"
   ]
  },
  {
   "cell_type": "code",
   "execution_count": 2,
   "id": "7793d21d-607d-462b-ac15-ce084d9c1e86",
   "metadata": {},
   "outputs": [
    {
     "ename": "SyntaxError",
     "evalue": "invalid syntax (258000529.py, line 1)",
     "output_type": "error",
     "traceback": [
      "\u001b[0;36m  Cell \u001b[0;32mIn [2], line 1\u001b[0;36m\u001b[0m\n\u001b[0;31m    pytao -init tao.init\u001b[0m\n\u001b[0m                ^\u001b[0m\n\u001b[0;31mSyntaxError\u001b[0m\u001b[0;31m:\u001b[0m invalid syntax\n"
     ]
    }
   ],
   "source": [
    "pytao -init tao.init"
   ]
  },
  {
   "cell_type": "code",
   "execution_count": 3,
   "id": "387d2e8f-dd50-472c-9faa-fb31b62b7490",
   "metadata": {},
   "outputs": [
    {
     "ename": "ValueError",
     "evalue": "The python kernel does not appear to be a conda environment.  Please use ``%pip install`` instead.",
     "output_type": "error",
     "traceback": [
      "\u001b[0;31m---------------------------------------------------------------------------\u001b[0m",
      "\u001b[0;31mValueError\u001b[0m                                Traceback (most recent call last)",
      "Cell \u001b[0;32mIn [3], line 1\u001b[0m\n\u001b[0;32m----> 1\u001b[0m \u001b[43mget_ipython\u001b[49m\u001b[43m(\u001b[49m\u001b[43m)\u001b[49m\u001b[38;5;241;43m.\u001b[39;49m\u001b[43mrun_line_magic\u001b[49m\u001b[43m(\u001b[49m\u001b[38;5;124;43m'\u001b[39;49m\u001b[38;5;124;43mconda\u001b[39;49m\u001b[38;5;124;43m'\u001b[39;49m\u001b[43m,\u001b[49m\u001b[43m \u001b[49m\u001b[38;5;124;43m'\u001b[39;49m\u001b[38;5;124;43minstall conda-forge::pytao\u001b[39;49m\u001b[38;5;124;43m'\u001b[39;49m\u001b[43m)\u001b[49m\n",
      "File \u001b[0;32m/usr/local/Cellar/jupyterlab/3.4.7/libexec/lib/python3.10/site-packages/IPython/core/interactiveshell.py:2309\u001b[0m, in \u001b[0;36mInteractiveShell.run_line_magic\u001b[0;34m(self, magic_name, line, _stack_depth)\u001b[0m\n\u001b[1;32m   2307\u001b[0m     kwargs[\u001b[38;5;124m'\u001b[39m\u001b[38;5;124mlocal_ns\u001b[39m\u001b[38;5;124m'\u001b[39m] \u001b[38;5;241m=\u001b[39m \u001b[38;5;28mself\u001b[39m\u001b[38;5;241m.\u001b[39mget_local_scope(stack_depth)\n\u001b[1;32m   2308\u001b[0m \u001b[38;5;28;01mwith\u001b[39;00m \u001b[38;5;28mself\u001b[39m\u001b[38;5;241m.\u001b[39mbuiltin_trap:\n\u001b[0;32m-> 2309\u001b[0m     result \u001b[38;5;241m=\u001b[39m \u001b[43mfn\u001b[49m\u001b[43m(\u001b[49m\u001b[38;5;241;43m*\u001b[39;49m\u001b[43margs\u001b[49m\u001b[43m,\u001b[49m\u001b[43m \u001b[49m\u001b[38;5;241;43m*\u001b[39;49m\u001b[38;5;241;43m*\u001b[39;49m\u001b[43mkwargs\u001b[49m\u001b[43m)\u001b[49m\n\u001b[1;32m   2310\u001b[0m \u001b[38;5;28;01mreturn\u001b[39;00m result\n",
      "File \u001b[0;32m/usr/local/Cellar/jupyterlab/3.4.7/libexec/lib/python3.10/site-packages/IPython/core/magics/packaging.py:87\u001b[0m, in \u001b[0;36mPackagingMagics.conda\u001b[0;34m(self, line)\u001b[0m\n\u001b[1;32m     81\u001b[0m \u001b[38;5;124;03m\"\"\"Run the conda package manager within the current kernel.\u001b[39;00m\n\u001b[1;32m     82\u001b[0m \n\u001b[1;32m     83\u001b[0m \u001b[38;5;124;03mUsage:\u001b[39;00m\n\u001b[1;32m     84\u001b[0m \u001b[38;5;124;03m  %conda install [pkgs]\u001b[39;00m\n\u001b[1;32m     85\u001b[0m \u001b[38;5;124;03m\"\"\"\u001b[39;00m\n\u001b[1;32m     86\u001b[0m \u001b[38;5;28;01mif\u001b[39;00m \u001b[38;5;129;01mnot\u001b[39;00m _is_conda_environment():\n\u001b[0;32m---> 87\u001b[0m     \u001b[38;5;28;01mraise\u001b[39;00m \u001b[38;5;167;01mValueError\u001b[39;00m(\u001b[38;5;124m\"\u001b[39m\u001b[38;5;124mThe python kernel does not appear to be a conda environment.  \u001b[39m\u001b[38;5;124m\"\u001b[39m\n\u001b[1;32m     88\u001b[0m                      \u001b[38;5;124m\"\u001b[39m\u001b[38;5;124mPlease use ``\u001b[39m\u001b[38;5;124m%\u001b[39m\u001b[38;5;124mpip install`` instead.\u001b[39m\u001b[38;5;124m\"\u001b[39m)\n\u001b[1;32m     90\u001b[0m conda \u001b[38;5;241m=\u001b[39m _get_conda_executable()\n\u001b[1;32m     91\u001b[0m args \u001b[38;5;241m=\u001b[39m shlex\u001b[38;5;241m.\u001b[39msplit(line)\n",
      "\u001b[0;31mValueError\u001b[0m: The python kernel does not appear to be a conda environment.  Please use ``%pip install`` instead."
     ]
    }
   ],
   "source": [
    "conda install conda-forge::pytao"
   ]
  },
  {
   "cell_type": "code",
   "execution_count": 5,
   "id": "f32591ec-7529-4040-a03d-c677a77adc20",
   "metadata": {},
   "outputs": [
    {
     "ename": "ValueError",
     "evalue": "The python kernel does not appear to be a conda environment.  Please use ``%pip install`` instead.",
     "output_type": "error",
     "traceback": [
      "\u001b[0;31m---------------------------------------------------------------------------\u001b[0m",
      "\u001b[0;31mValueError\u001b[0m                                Traceback (most recent call last)",
      "Cell \u001b[0;32mIn [5], line 1\u001b[0m\n\u001b[0;32m----> 1\u001b[0m \u001b[43mget_ipython\u001b[49m\u001b[43m(\u001b[49m\u001b[43m)\u001b[49m\u001b[38;5;241;43m.\u001b[39;49m\u001b[43mrun_line_magic\u001b[49m\u001b[43m(\u001b[49m\u001b[38;5;124;43m'\u001b[39;49m\u001b[38;5;124;43mconda\u001b[39;49m\u001b[38;5;124;43m'\u001b[39;49m\u001b[43m,\u001b[49m\u001b[43m \u001b[49m\u001b[38;5;124;43m'\u001b[39;49m\u001b[38;5;124;43minstall -c conda-forge bmad\u001b[39;49m\u001b[38;5;124;43m'\u001b[39;49m\u001b[43m)\u001b[49m\n",
      "File \u001b[0;32m/usr/local/Cellar/jupyterlab/3.4.7/libexec/lib/python3.10/site-packages/IPython/core/interactiveshell.py:2309\u001b[0m, in \u001b[0;36mInteractiveShell.run_line_magic\u001b[0;34m(self, magic_name, line, _stack_depth)\u001b[0m\n\u001b[1;32m   2307\u001b[0m     kwargs[\u001b[38;5;124m'\u001b[39m\u001b[38;5;124mlocal_ns\u001b[39m\u001b[38;5;124m'\u001b[39m] \u001b[38;5;241m=\u001b[39m \u001b[38;5;28mself\u001b[39m\u001b[38;5;241m.\u001b[39mget_local_scope(stack_depth)\n\u001b[1;32m   2308\u001b[0m \u001b[38;5;28;01mwith\u001b[39;00m \u001b[38;5;28mself\u001b[39m\u001b[38;5;241m.\u001b[39mbuiltin_trap:\n\u001b[0;32m-> 2309\u001b[0m     result \u001b[38;5;241m=\u001b[39m \u001b[43mfn\u001b[49m\u001b[43m(\u001b[49m\u001b[38;5;241;43m*\u001b[39;49m\u001b[43margs\u001b[49m\u001b[43m,\u001b[49m\u001b[43m \u001b[49m\u001b[38;5;241;43m*\u001b[39;49m\u001b[38;5;241;43m*\u001b[39;49m\u001b[43mkwargs\u001b[49m\u001b[43m)\u001b[49m\n\u001b[1;32m   2310\u001b[0m \u001b[38;5;28;01mreturn\u001b[39;00m result\n",
      "File \u001b[0;32m/usr/local/Cellar/jupyterlab/3.4.7/libexec/lib/python3.10/site-packages/IPython/core/magics/packaging.py:87\u001b[0m, in \u001b[0;36mPackagingMagics.conda\u001b[0;34m(self, line)\u001b[0m\n\u001b[1;32m     81\u001b[0m \u001b[38;5;124;03m\"\"\"Run the conda package manager within the current kernel.\u001b[39;00m\n\u001b[1;32m     82\u001b[0m \n\u001b[1;32m     83\u001b[0m \u001b[38;5;124;03mUsage:\u001b[39;00m\n\u001b[1;32m     84\u001b[0m \u001b[38;5;124;03m  %conda install [pkgs]\u001b[39;00m\n\u001b[1;32m     85\u001b[0m \u001b[38;5;124;03m\"\"\"\u001b[39;00m\n\u001b[1;32m     86\u001b[0m \u001b[38;5;28;01mif\u001b[39;00m \u001b[38;5;129;01mnot\u001b[39;00m _is_conda_environment():\n\u001b[0;32m---> 87\u001b[0m     \u001b[38;5;28;01mraise\u001b[39;00m \u001b[38;5;167;01mValueError\u001b[39;00m(\u001b[38;5;124m\"\u001b[39m\u001b[38;5;124mThe python kernel does not appear to be a conda environment.  \u001b[39m\u001b[38;5;124m\"\u001b[39m\n\u001b[1;32m     88\u001b[0m                      \u001b[38;5;124m\"\u001b[39m\u001b[38;5;124mPlease use ``\u001b[39m\u001b[38;5;124m%\u001b[39m\u001b[38;5;124mpip install`` instead.\u001b[39m\u001b[38;5;124m\"\u001b[39m)\n\u001b[1;32m     90\u001b[0m conda \u001b[38;5;241m=\u001b[39m _get_conda_executable()\n\u001b[1;32m     91\u001b[0m args \u001b[38;5;241m=\u001b[39m shlex\u001b[38;5;241m.\u001b[39msplit(line)\n",
      "\u001b[0;31mValueError\u001b[0m: The python kernel does not appear to be a conda environment.  Please use ``%pip install`` instead."
     ]
    }
   ],
   "source": [
    "conda install -c conda-forge bmad"
   ]
  },
  {
   "cell_type": "code",
   "execution_count": 7,
   "id": "c342531e-99fe-470d-9c8a-19e42f5046e8",
   "metadata": {},
   "outputs": [
    {
     "ename": "ValueError",
     "evalue": "The python kernel does not appear to be a conda environment.  Please use ``%pip install`` instead.",
     "output_type": "error",
     "traceback": [
      "\u001b[0;31m---------------------------------------------------------------------------\u001b[0m",
      "\u001b[0;31mValueError\u001b[0m                                Traceback (most recent call last)",
      "Cell \u001b[0;32mIn [7], line 1\u001b[0m\n\u001b[0;32m----> 1\u001b[0m \u001b[43mget_ipython\u001b[49m\u001b[43m(\u001b[49m\u001b[43m)\u001b[49m\u001b[38;5;241;43m.\u001b[39;49m\u001b[43mrun_line_magic\u001b[49m\u001b[43m(\u001b[49m\u001b[38;5;124;43m'\u001b[39;49m\u001b[38;5;124;43mconda\u001b[39;49m\u001b[38;5;124;43m'\u001b[39;49m\u001b[43m,\u001b[49m\u001b[43m \u001b[49m\u001b[38;5;124;43m'\u001b[39;49m\u001b[38;5;124;43mcreate -n myenv python=3.10\u001b[39;49m\u001b[38;5;124;43m'\u001b[39;49m\u001b[43m)\u001b[49m\n",
      "File \u001b[0;32m/usr/local/Cellar/jupyterlab/3.4.7/libexec/lib/python3.10/site-packages/IPython/core/interactiveshell.py:2309\u001b[0m, in \u001b[0;36mInteractiveShell.run_line_magic\u001b[0;34m(self, magic_name, line, _stack_depth)\u001b[0m\n\u001b[1;32m   2307\u001b[0m     kwargs[\u001b[38;5;124m'\u001b[39m\u001b[38;5;124mlocal_ns\u001b[39m\u001b[38;5;124m'\u001b[39m] \u001b[38;5;241m=\u001b[39m \u001b[38;5;28mself\u001b[39m\u001b[38;5;241m.\u001b[39mget_local_scope(stack_depth)\n\u001b[1;32m   2308\u001b[0m \u001b[38;5;28;01mwith\u001b[39;00m \u001b[38;5;28mself\u001b[39m\u001b[38;5;241m.\u001b[39mbuiltin_trap:\n\u001b[0;32m-> 2309\u001b[0m     result \u001b[38;5;241m=\u001b[39m \u001b[43mfn\u001b[49m\u001b[43m(\u001b[49m\u001b[38;5;241;43m*\u001b[39;49m\u001b[43margs\u001b[49m\u001b[43m,\u001b[49m\u001b[43m \u001b[49m\u001b[38;5;241;43m*\u001b[39;49m\u001b[38;5;241;43m*\u001b[39;49m\u001b[43mkwargs\u001b[49m\u001b[43m)\u001b[49m\n\u001b[1;32m   2310\u001b[0m \u001b[38;5;28;01mreturn\u001b[39;00m result\n",
      "File \u001b[0;32m/usr/local/Cellar/jupyterlab/3.4.7/libexec/lib/python3.10/site-packages/IPython/core/magics/packaging.py:87\u001b[0m, in \u001b[0;36mPackagingMagics.conda\u001b[0;34m(self, line)\u001b[0m\n\u001b[1;32m     81\u001b[0m \u001b[38;5;124;03m\"\"\"Run the conda package manager within the current kernel.\u001b[39;00m\n\u001b[1;32m     82\u001b[0m \n\u001b[1;32m     83\u001b[0m \u001b[38;5;124;03mUsage:\u001b[39;00m\n\u001b[1;32m     84\u001b[0m \u001b[38;5;124;03m  %conda install [pkgs]\u001b[39;00m\n\u001b[1;32m     85\u001b[0m \u001b[38;5;124;03m\"\"\"\u001b[39;00m\n\u001b[1;32m     86\u001b[0m \u001b[38;5;28;01mif\u001b[39;00m \u001b[38;5;129;01mnot\u001b[39;00m _is_conda_environment():\n\u001b[0;32m---> 87\u001b[0m     \u001b[38;5;28;01mraise\u001b[39;00m \u001b[38;5;167;01mValueError\u001b[39;00m(\u001b[38;5;124m\"\u001b[39m\u001b[38;5;124mThe python kernel does not appear to be a conda environment.  \u001b[39m\u001b[38;5;124m\"\u001b[39m\n\u001b[1;32m     88\u001b[0m                      \u001b[38;5;124m\"\u001b[39m\u001b[38;5;124mPlease use ``\u001b[39m\u001b[38;5;124m%\u001b[39m\u001b[38;5;124mpip install`` instead.\u001b[39m\u001b[38;5;124m\"\u001b[39m)\n\u001b[1;32m     90\u001b[0m conda \u001b[38;5;241m=\u001b[39m _get_conda_executable()\n\u001b[1;32m     91\u001b[0m args \u001b[38;5;241m=\u001b[39m shlex\u001b[38;5;241m.\u001b[39msplit(line)\n",
      "\u001b[0;31mValueError\u001b[0m: The python kernel does not appear to be a conda environment.  Please use ``%pip install`` instead."
     ]
    }
   ],
   "source": [
    "conda create -n myenv python=3.10"
   ]
  },
  {
   "cell_type": "code",
   "execution_count": 8,
   "id": "fb04645d-c5e1-48d7-bffb-8ae85ac27f2b",
   "metadata": {},
   "outputs": [
    {
     "ename": "ValueError",
     "evalue": "The python kernel does not appear to be a conda environment.  Please use ``%pip install`` instead.",
     "output_type": "error",
     "traceback": [
      "\u001b[0;31m---------------------------------------------------------------------------\u001b[0m",
      "\u001b[0;31mValueError\u001b[0m                                Traceback (most recent call last)",
      "Cell \u001b[0;32mIn [8], line 1\u001b[0m\n\u001b[0;32m----> 1\u001b[0m \u001b[43mget_ipython\u001b[49m\u001b[43m(\u001b[49m\u001b[43m)\u001b[49m\u001b[38;5;241;43m.\u001b[39;49m\u001b[43mrun_line_magic\u001b[49m\u001b[43m(\u001b[49m\u001b[38;5;124;43m'\u001b[39;49m\u001b[38;5;124;43mconda\u001b[39;49m\u001b[38;5;124;43m'\u001b[39;49m\u001b[43m,\u001b[49m\u001b[43m \u001b[49m\u001b[38;5;124;43m'\u001b[39;49m\u001b[38;5;124;43minstall ipykernel\u001b[39;49m\u001b[38;5;124;43m'\u001b[39;49m\u001b[43m)\u001b[49m\n",
      "File \u001b[0;32m/usr/local/Cellar/jupyterlab/3.4.7/libexec/lib/python3.10/site-packages/IPython/core/interactiveshell.py:2309\u001b[0m, in \u001b[0;36mInteractiveShell.run_line_magic\u001b[0;34m(self, magic_name, line, _stack_depth)\u001b[0m\n\u001b[1;32m   2307\u001b[0m     kwargs[\u001b[38;5;124m'\u001b[39m\u001b[38;5;124mlocal_ns\u001b[39m\u001b[38;5;124m'\u001b[39m] \u001b[38;5;241m=\u001b[39m \u001b[38;5;28mself\u001b[39m\u001b[38;5;241m.\u001b[39mget_local_scope(stack_depth)\n\u001b[1;32m   2308\u001b[0m \u001b[38;5;28;01mwith\u001b[39;00m \u001b[38;5;28mself\u001b[39m\u001b[38;5;241m.\u001b[39mbuiltin_trap:\n\u001b[0;32m-> 2309\u001b[0m     result \u001b[38;5;241m=\u001b[39m \u001b[43mfn\u001b[49m\u001b[43m(\u001b[49m\u001b[38;5;241;43m*\u001b[39;49m\u001b[43margs\u001b[49m\u001b[43m,\u001b[49m\u001b[43m \u001b[49m\u001b[38;5;241;43m*\u001b[39;49m\u001b[38;5;241;43m*\u001b[39;49m\u001b[43mkwargs\u001b[49m\u001b[43m)\u001b[49m\n\u001b[1;32m   2310\u001b[0m \u001b[38;5;28;01mreturn\u001b[39;00m result\n",
      "File \u001b[0;32m/usr/local/Cellar/jupyterlab/3.4.7/libexec/lib/python3.10/site-packages/IPython/core/magics/packaging.py:87\u001b[0m, in \u001b[0;36mPackagingMagics.conda\u001b[0;34m(self, line)\u001b[0m\n\u001b[1;32m     81\u001b[0m \u001b[38;5;124;03m\"\"\"Run the conda package manager within the current kernel.\u001b[39;00m\n\u001b[1;32m     82\u001b[0m \n\u001b[1;32m     83\u001b[0m \u001b[38;5;124;03mUsage:\u001b[39;00m\n\u001b[1;32m     84\u001b[0m \u001b[38;5;124;03m  %conda install [pkgs]\u001b[39;00m\n\u001b[1;32m     85\u001b[0m \u001b[38;5;124;03m\"\"\"\u001b[39;00m\n\u001b[1;32m     86\u001b[0m \u001b[38;5;28;01mif\u001b[39;00m \u001b[38;5;129;01mnot\u001b[39;00m _is_conda_environment():\n\u001b[0;32m---> 87\u001b[0m     \u001b[38;5;28;01mraise\u001b[39;00m \u001b[38;5;167;01mValueError\u001b[39;00m(\u001b[38;5;124m\"\u001b[39m\u001b[38;5;124mThe python kernel does not appear to be a conda environment.  \u001b[39m\u001b[38;5;124m\"\u001b[39m\n\u001b[1;32m     88\u001b[0m                      \u001b[38;5;124m\"\u001b[39m\u001b[38;5;124mPlease use ``\u001b[39m\u001b[38;5;124m%\u001b[39m\u001b[38;5;124mpip install`` instead.\u001b[39m\u001b[38;5;124m\"\u001b[39m)\n\u001b[1;32m     90\u001b[0m conda \u001b[38;5;241m=\u001b[39m _get_conda_executable()\n\u001b[1;32m     91\u001b[0m args \u001b[38;5;241m=\u001b[39m shlex\u001b[38;5;241m.\u001b[39msplit(line)\n",
      "\u001b[0;31mValueError\u001b[0m: The python kernel does not appear to be a conda environment.  Please use ``%pip install`` instead."
     ]
    }
   ],
   "source": [
    "conda install ipykernel"
   ]
  },
  {
   "cell_type": "code",
   "execution_count": 13,
   "id": "8103d3ed-b56e-40fd-a8e3-3920ed3c50c7",
   "metadata": {},
   "outputs": [
    {
     "ename": "SyntaxError",
     "evalue": "invalid syntax (1438192175.py, line 1)",
     "output_type": "error",
     "traceback": [
      "\u001b[0;36m  Cell \u001b[0;32mIn [13], line 1\u001b[0;36m\u001b[0m\n\u001b[0;31m    which tao\u001b[0m\n\u001b[0m          ^\u001b[0m\n\u001b[0;31mSyntaxError\u001b[0m\u001b[0;31m:\u001b[0m invalid syntax\n"
     ]
    }
   ],
   "source": [
    "which tao"
   ]
  },
  {
   "cell_type": "code",
   "execution_count": null,
   "id": "1f249427-5a52-49d4-b2de-16a06ea4ba66",
   "metadata": {},
   "outputs": [],
   "source": []
  }
 ],
 "metadata": {
  "kernelspec": {
   "display_name": "Python 3 (ipykernel)",
   "language": "python",
   "name": "python3"
  },
  "language_info": {
   "codemirror_mode": {
    "name": "ipython",
    "version": 3
   },
   "file_extension": ".py",
   "mimetype": "text/x-python",
   "name": "python",
   "nbconvert_exporter": "python",
   "pygments_lexer": "ipython3",
   "version": "3.10.6"
  }
 },
 "nbformat": 4,
 "nbformat_minor": 5
}
